<?xml version="1.0"?>

<robot name="robot">

  <!-- Color of materials -->
  <material name="yellow">
    <color rgba="1 1 0 1"/>
  </material>
  <material name="blue">
    <color rgba="0 0 1 1"/>
  </material>
  <material name="red">
    <color rgba="1 0 0 1"/>
  </material>

  <link name="base_link">
    <visual>
      <geometry>
        <cylinder length="0.01" radius="0.2"/>
      </geometry>
      <origin rpy="0 0 0" xyz="0 0 0"/>
      <material name="yellow" />
    </visual>
    <collision>
      <origin xyz="0 0 0" rpy="0 0 0" />
      <geometry>
        <cylinder length="0.01" radius="0.2"/>
      </geometry>
    </collision>
    <inertial>
      <mass value="1" />
      <inertia ixx="1.0" ixy="0.0" ixz="0.0" iyy="0.5" iyz="0.0" izz="1.0" />
    </inertial>
  </link>
  <gazebo reference="base_link">
    <material>Gazebo/White</material>
  </gazebo>

  <joint name="pan_joint" type="revolute">
    <parent link="base_link"/>
    <child link="pan_link"/>
    <origin xyz="0 0 0"/>
    <axis xyz="0 0 1" />
    <limit effort="300" velocity="0.1" lower="-3.1" upper="3.1"/>
    <dynamics damping="50" friction="1"/>
  </joint>

  <link name="pan_link">
    <visual>
      <geometry>
        <cylinder length="0.4" radius="0.04"/>
      </geometry>
      <origin rpy="0 0 0" xyz="0 0 0.2"/>
      <material name="blue" />
    </visual>
    <collision>
      <origin rpy="0 0 0" xyz="0 0 0.2"/>
      <geometry>
        <cylinder length="0.4" radius="0.04"/>
      </geometry>
    </collision>
    <inertial>
      <mass value="1" />
      <inertia ixx="1.0" ixy="0.0" ixz="0.0" iyy="0.5" iyz="0.0" izz="1.0" />
    </inertial>
  </link>
  <gazebo reference="pan_link">
    <material>Gazebo/Red</material>
  </gazebo>

  <joint name="tilt_joint" type="revolute">
    <parent link="pan_link"/>
    <child link="tilt_link"/>
    <origin xyz="0 0 0.4"/>
    <axis xyz="0 1 0" />
    <limit effort="300" velocity="0.1" lower="-0.85" upper="0.85"/>
    <dynamics damping="50" friction="1"/>
  </joint>

  <link name="tilt_link">
    <visual>
      <geometry>
        <cylinder length="0.4" radius="0.04"/>
      </geometry>
      <origin rpy="0 1.57 0" xyz="0 0 0"/>
      <material name="red" />
    </visual>
    <collision>
      <origin rpy="0 1.57 0" xyz="0 0 0"/>
      <geometry>
        <cylinder length="0.4" radius="0.04"/>
      </geometry>
    </collision>
    <inertial>
      <mass value="1" />
      <inertia ixx="1.0" ixy="0.0" ixz="0.0" iyy="0.5" iyz="0.0" izz="1.0" />
    </inertial>
  </link>
  <gazebo reference="tilt_link">
    <material>Gazebo/White</material>
  </gazebo>

  <!-- Transmissions -->
  <transmission name="tran1">
    <type>transmission_interface/SimpleTransmission</type>
    <joint name="pan_joint">
      <hardwareInterface>hardware_interface/EffortJointInterface</hardwareInterface>
    </joint>
    <actuator name="motor1">
      <hardwareInterface>hardware_interface/EffortJointInterface</hardwareInterface>
      <mechanicalReduction>1</mechanicalReduction>
    </actuator>
  </transmission>

  <transmission name="tran2">
    <type>transmission_interface/SimpleTransmission</type>
    <joint name="tilt_joint">
      <hardwareInterface>hardware_interface/EffortJointInterface</hardwareInterface>
    </joint>
    <actuator name="motor2">
      <hardwareInterface>hardware_interface/EffortJointInterface</hardwareInterface>
      <mechanicalReduction>1</mechanicalReduction>
    </actuator>
  </transmission>

   <!-- Plugin: ros_control -->
   <gazebo>
     <plugin name="gazebo_ros_control" filename="libgazebo_ros_control.so">
       <robotNamespace>/robot</robotNamespace>
       <legacyModeNS>true</legacyModeNS>
     </plugin>
   </gazebo>

</robot>
